<?xml version="1.0" encoding="utf-8"?>
<!-- This URDF was automatically created by SolidWorks to URDF Exporter! Originally created by Stephen Brawner (brawner@gmail.com) 
     Commit Version: 1.6.0-4-g7f85cfe  Build Version: 1.6.7995.38578
     For more information, please see http://wiki.ros.org/sw_urdf_exporter -->
<robot
  name="bolt">
  <link
    name="world"> 
  </link>
  <link
    name="bolt_base">
    <inertial>
      <origin
        xyz="-3.0323E-35 -0.014681 2.1398E-18"
        rpy="0 0 0" />
      <mass
        value="0.035437" />
      <inertia
        ixx="6.4414E-06"
        ixy="8.6179E-39"
        ixz="-2.2905E-38"
        iyy="7.4991E-06"
        iyz="-1.8524E-22"
        izz="6.4414E-06" />
    </inertial>
    <visual>
      <origin
        xyz="0 0 0"
        rpy="0 0 0" />
      <geometry>
        <mesh
          filename="../meshes/bolt_base.obj" />
      </geometry>
      <material
        name="">
        <color
          rgba="0.79216 0.81961 0.93333 1" />
      </material>
    </visual>
    <collision>
      <origin
        xyz="0 0 0"
        rpy="0 0 0" />
      <geometry>
        <cylinder radius="0.020" length="0.030" />
      </geometry>
    </collision>
  </link>
  <joint name="bolt_base_joint" type="fixed">
    <parent link="world"/>
    <child link="bolt_base"/>
    <origin xyz="0 0 0" rpy="0 0 0"/>
  </joint>
  <link
    name="bolt_pris">
    <inertial>
      <origin
        xyz="-3.0436E-35 1.5359E-18 0.02"
        rpy="0 0 0" />
      <mass
        value="0.0012566" />
      <inertia
        ixx="5.8224E-08"
        ixy="-1.6409E-40"
        ixz="-7.2852E-41"
        iyy="5.8224E-08"
        iyz="-7.6739E-25"
        izz="3.2673E-08" />
    </inertial>
    <visual>
      <origin
        xyz="0 0 0"
        rpy="0 0 0" />
      <geometry>
        <mesh
          filename="../meshes/bolt_pris.obj" />
      </geometry>
      <material
        name="">
        <color
          rgba="0.79216 0.81961 0.93333 1" />
      </material>
    </visual>
    
  </link>
  <joint
    name="bolt_pris_joint"
    type="prismatic">
    <origin
      xyz="0 0 0"
      rpy="0 0 0" />
    <parent
      link="bolt_base" />
    <child
      link="bolt_pris" />
    <axis
      xyz="0 0 1" />
    <limit 
      lower="-0.1" 
      upper="0.1" 
      effort="1000" 
      velocity="100" />
    <dynamics 
      damping="0" 
      friction="0" />
  </joint>
  <link
    name="bolt_rev">
    <inertial>
      <origin
        xyz="6.4362E-24 1.2409E-18 0.014681"
        rpy="0 0 0" />
      <mass
        value="0.01286" />
      <inertia
        ixx="0.18177E-5"
        ixy="-1.5888E-24"
        ixz="-1.1391E-22"
        iyy="0.18177E-5"
        iyz="3.4001E-18"
        izz="0.21162E-5" />
    </inertial>
    <visual>
      <origin
        xyz="0 0 0"
        rpy="0 0 0" />
      <geometry>
        <mesh
          filename="../meshes/bolt_rev.obj" />
      </geometry>
      <material
        name="">
        <color
          rgba="1 1 1 1" />
      </material>
    </visual>
    <collision>
      <origin xyz="0 0 0.004" rpy="0 0 0.5236" /> 
      <geometry>
        <box size="0.0219 0.011 0.008" />
      </geometry>
    </collision>
    <collision>
      <origin xyz="0 0 0.004" rpy="0 0 1.5708" /> 
      <geometry>
        <box size="0.0219 0.011 0.008" />
      </geometry>
    </collision>
    <collision>
      <origin xyz="0 0 0.004" rpy="0 0 -0.5236" /> 
      <geometry>
        <box size="0.0219 0.011 0.008" />
      </geometry>
    </collision>
    <collision>
      <origin xyz="0 0 -0.01" rpy="0 0 0" />
      <geometry>
        <cylinder radius="0.006" length="0.02" />
      </geometry>
    </collision>
  </link>
  <joint
    name="bolt_rev_joint"
    type="continuous">
    <origin
      xyz="0 0 0.03"
      rpy="0 0 0" />
    <parent
      link="bolt_pris" />
    <child
      link="bolt_rev" />
    <axis
      xyz="0 0 1" />
    <limit
      effort="1000"
      velocity="100" />
    <dynamics
      damping="0.01"
      friction="0.01" />
  </joint>
</robot>